2023-04-25 21:08:38,355 INFO    StreamThr :59834 [internal.py:wandb_internal():86] W&B internal server running at pid: 59834, started at: 2023-04-25 21:08:38.354045
2023-04-25 21:08:38,363 DEBUG   HandlerThread:59834 [handler.py:handle_request():144] handle_request: status
2023-04-25 21:08:38,366 INFO    WriterThread:59834 [datastore.py:open_for_write():85] open: /root/workspace/myq_206/server-master/wandb/run-20230425_210838-m3uey92d/run-m3uey92d.wandb
2023-04-25 21:08:38,367 DEBUG   SenderThread:59834 [sender.py:send():375] send: header
2023-04-25 21:08:38,367 DEBUG   SenderThread:59834 [sender.py:send():375] send: run
2023-04-25 21:08:41,607 INFO    SenderThread:59834 [retry.py:__call__():172] Retry attempt failed:
Traceback (most recent call last):
  File "/root/miniconda3/envs/myq_py38/lib/python3.8/site-packages/urllib3/connectionpool.py", line 703, in urlopen
    httplib_response = self._make_request(
  File "/root/miniconda3/envs/myq_py38/lib/python3.8/site-packages/urllib3/connectionpool.py", line 386, in _make_request
    self._validate_conn(conn)
  File "/root/miniconda3/envs/myq_py38/lib/python3.8/site-packages/urllib3/connectionpool.py", line 1042, in _validate_conn
    conn.connect()
  File "/root/miniconda3/envs/myq_py38/lib/python3.8/site-packages/urllib3/connection.py", line 472, in connect
    _match_hostname(cert, self.assert_hostname or server_hostname)
  File "/root/miniconda3/envs/myq_py38/lib/python3.8/site-packages/urllib3/connection.py", line 545, in _match_hostname
    match_hostname(cert, asserted_hostname)
  File "/root/miniconda3/envs/myq_py38/lib/python3.8/site-packages/urllib3/util/ssl_match_hostname.py", line 150, in match_hostname
    raise CertificateError(
urllib3.util.ssl_match_hostname.CertificateError: hostname 'api.wandb.ai' doesn't match either of '*.gxnu.edu.cn', 'gxnu.edu.cn'

During handling of the above exception, another exception occurred:

Traceback (most recent call last):
  File "/root/miniconda3/envs/myq_py38/lib/python3.8/site-packages/requests/adapters.py", line 489, in send
    resp = conn.urlopen(
  File "/root/miniconda3/envs/myq_py38/lib/python3.8/site-packages/urllib3/connectionpool.py", line 787, in urlopen
    retries = retries.increment(
  File "/root/miniconda3/envs/myq_py38/lib/python3.8/site-packages/urllib3/util/retry.py", line 592, in increment
    raise MaxRetryError(_pool, url, error or ResponseError(cause))
urllib3.exceptions.MaxRetryError: HTTPSConnectionPool(host='api.wandb.ai', port=443): Max retries exceeded with url: /graphql (Caused by SSLError(CertificateError("hostname 'api.wandb.ai' doesn't match either of '*.gxnu.edu.cn', 'gxnu.edu.cn'")))

During handling of the above exception, another exception occurred:

Traceback (most recent call last):
  File "/root/miniconda3/envs/myq_py38/lib/python3.8/site-packages/wandb/sdk/lib/retry.py", line 131, in __call__
    result = self._call_fn(*args, **kwargs)
  File "/root/miniconda3/envs/myq_py38/lib/python3.8/site-packages/wandb/sdk/internal/internal_api.py", line 285, in execute
    return self.client.execute(*args, **kwargs)  # type: ignore
  File "/root/miniconda3/envs/myq_py38/lib/python3.8/site-packages/wandb/vendor/gql-0.2.0/wandb_gql/client.py", line 52, in execute
    result = self._get_result(document, *args, **kwargs)
  File "/root/miniconda3/envs/myq_py38/lib/python3.8/site-packages/wandb/vendor/gql-0.2.0/wandb_gql/client.py", line 60, in _get_result
    return self.transport.execute(document, *args, **kwargs)
  File "/root/miniconda3/envs/myq_py38/lib/python3.8/site-packages/wandb/sdk/lib/gql_request.py", line 55, in execute
    request = self.session.post(self.url, **post_args)
  File "/root/miniconda3/envs/myq_py38/lib/python3.8/site-packages/requests/sessions.py", line 635, in post
    return self.request("POST", url, data=data, json=json, **kwargs)
  File "/root/miniconda3/envs/myq_py38/lib/python3.8/site-packages/requests/sessions.py", line 587, in request
    resp = self.send(prep, **send_kwargs)
  File "/root/miniconda3/envs/myq_py38/lib/python3.8/site-packages/requests/sessions.py", line 701, in send
    r = adapter.send(request, **kwargs)
  File "/root/miniconda3/envs/myq_py38/lib/python3.8/site-packages/requests/adapters.py", line 563, in send
    raise SSLError(e, request=request)
requests.exceptions.SSLError: HTTPSConnectionPool(host='api.wandb.ai', port=443): Max retries exceeded with url: /graphql (Caused by SSLError(CertificateError("hostname 'api.wandb.ai' doesn't match either of '*.gxnu.edu.cn', 'gxnu.edu.cn'")))
2023-04-25 21:08:43,361 DEBUG   HandlerThread:59834 [handler.py:handle_request():144] handle_request: keepalive
2023-04-25 21:08:48,362 DEBUG   HandlerThread:59834 [handler.py:handle_request():144] handle_request: keepalive
2023-04-25 21:08:53,364 DEBUG   HandlerThread:59834 [handler.py:handle_request():144] handle_request: keepalive
2023-04-25 21:08:58,366 DEBUG   HandlerThread:59834 [handler.py:handle_request():144] handle_request: keepalive
2023-04-25 21:09:03,368 DEBUG   HandlerThread:59834 [handler.py:handle_request():144] handle_request: keepalive
2023-04-25 21:09:08,370 DEBUG   HandlerThread:59834 [handler.py:handle_request():144] handle_request: keepalive
2023-04-25 21:09:13,372 DEBUG   HandlerThread:59834 [handler.py:handle_request():144] handle_request: keepalive
2023-04-25 21:09:18,374 DEBUG   HandlerThread:59834 [handler.py:handle_request():144] handle_request: keepalive
2023-04-25 21:09:23,376 DEBUG   HandlerThread:59834 [handler.py:handle_request():144] handle_request: keepalive
2023-04-25 21:09:28,378 DEBUG   HandlerThread:59834 [handler.py:handle_request():144] handle_request: keepalive
2023-04-25 21:09:33,380 DEBUG   HandlerThread:59834 [handler.py:handle_request():144] handle_request: keepalive
2023-04-25 21:09:38,382 DEBUG   HandlerThread:59834 [handler.py:handle_request():144] handle_request: cancel
2023-04-25 21:09:38,382 DEBUG   HandlerThread:59834 [handler.py:handle_request():144] handle_request: cancel
2023-04-25 21:09:38,383 DEBUG   SenderThread:59834 [sender.py:send():384] Record cancelled: run
2023-04-25 21:09:38,384 DEBUG   HandlerThread:59834 [handler.py:handle_request():144] handle_request: status_report
2023-04-25 21:09:43,385 DEBUG   HandlerThread:59834 [handler.py:handle_request():144] handle_request: status_report
2023-04-25 21:09:48,386 DEBUG   HandlerThread:59834 [handler.py:handle_request():144] handle_request: status_report
2023-04-25 21:09:53,387 DEBUG   HandlerThread:59834 [handler.py:handle_request():144] handle_request: status_report
2023-04-25 21:09:58,388 DEBUG   HandlerThread:59834 [handler.py:handle_request():144] handle_request: status_report
2023-04-25 21:10:03,390 DEBUG   HandlerThread:59834 [handler.py:handle_request():144] handle_request: status_report
2023-04-25 21:10:08,391 DEBUG   HandlerThread:59834 [handler.py:handle_request():144] handle_request: status_report
2023-04-25 21:10:13,392 DEBUG   HandlerThread:59834 [handler.py:handle_request():144] handle_request: status_report
2023-04-25 21:10:18,393 DEBUG   HandlerThread:59834 [handler.py:handle_request():144] handle_request: status_report
2023-04-25 21:10:23,394 DEBUG   HandlerThread:59834 [handler.py:handle_request():144] handle_request: status_report
2023-04-25 21:10:28,395 DEBUG   HandlerThread:59834 [handler.py:handle_request():144] handle_request: status_report
2023-04-25 21:10:33,396 DEBUG   HandlerThread:59834 [handler.py:handle_request():144] handle_request: status_report
2023-04-25 21:10:38,397 DEBUG   HandlerThread:59834 [handler.py:handle_request():144] handle_request: status_report
