2023-04-23 20:27:18,403 INFO    StreamThr :28076 [internal.py:wandb_internal():86] W&B internal server running at pid: 28076, started at: 2023-04-23 20:27:18.402643
2023-04-23 20:27:18,409 DEBUG   HandlerThread:28076 [handler.py:handle_request():144] handle_request: status
2023-04-23 20:27:18,414 INFO    WriterThread:28076 [datastore.py:open_for_write():85] open: /root/workspace/myq_206/server-master/wandb/run-20230423_202718-wvttj58m/run-wvttj58m.wandb
2023-04-23 20:27:18,416 DEBUG   SenderThread:28076 [sender.py:send():375] send: header
2023-04-23 20:27:18,416 DEBUG   SenderThread:28076 [sender.py:send():375] send: run
2023-04-23 20:27:22,038 INFO    SenderThread:28076 [retry.py:__call__():172] Retry attempt failed:
Traceback (most recent call last):
  File "/root/miniconda3/envs/myq_py38/lib/python3.8/site-packages/urllib3/connectionpool.py", line 703, in urlopen
    httplib_response = self._make_request(
  File "/root/miniconda3/envs/myq_py38/lib/python3.8/site-packages/urllib3/connectionpool.py", line 386, in _make_request
    self._validate_conn(conn)
  File "/root/miniconda3/envs/myq_py38/lib/python3.8/site-packages/urllib3/connectionpool.py", line 1042, in _validate_conn
    conn.connect()
  File "/root/miniconda3/envs/myq_py38/lib/python3.8/site-packages/urllib3/connection.py", line 472, in connect
    _match_hostname(cert, self.assert_hostname or server_hostname)
  File "/root/miniconda3/envs/myq_py38/lib/python3.8/site-packages/urllib3/connection.py", line 545, in _match_hostname
    match_hostname(cert, asserted_hostname)
  File "/root/miniconda3/envs/myq_py38/lib/python3.8/site-packages/urllib3/util/ssl_match_hostname.py", line 150, in match_hostname
    raise CertificateError(
urllib3.util.ssl_match_hostname.CertificateError: hostname 'api.wandb.ai' doesn't match either of '*.gxnu.edu.cn', 'gxnu.edu.cn'

During handling of the above exception, another exception occurred:

Traceback (most recent call last):
  File "/root/miniconda3/envs/myq_py38/lib/python3.8/site-packages/requests/adapters.py", line 489, in send
    resp = conn.urlopen(
  File "/root/miniconda3/envs/myq_py38/lib/python3.8/site-packages/urllib3/connectionpool.py", line 787, in urlopen
    retries = retries.increment(
  File "/root/miniconda3/envs/myq_py38/lib/python3.8/site-packages/urllib3/util/retry.py", line 592, in increment
    raise MaxRetryError(_pool, url, error or ResponseError(cause))
urllib3.exceptions.MaxRetryError: HTTPSConnectionPool(host='api.wandb.ai', port=443): Max retries exceeded with url: /graphql (Caused by SSLError(CertificateError("hostname 'api.wandb.ai' doesn't match either of '*.gxnu.edu.cn', 'gxnu.edu.cn'")))

During handling of the above exception, another exception occurred:

Traceback (most recent call last):
  File "/root/miniconda3/envs/myq_py38/lib/python3.8/site-packages/wandb/sdk/lib/retry.py", line 131, in __call__
    result = self._call_fn(*args, **kwargs)
  File "/root/miniconda3/envs/myq_py38/lib/python3.8/site-packages/wandb/sdk/internal/internal_api.py", line 285, in execute
    return self.client.execute(*args, **kwargs)  # type: ignore
  File "/root/miniconda3/envs/myq_py38/lib/python3.8/site-packages/wandb/vendor/gql-0.2.0/wandb_gql/client.py", line 52, in execute
    result = self._get_result(document, *args, **kwargs)
  File "/root/miniconda3/envs/myq_py38/lib/python3.8/site-packages/wandb/vendor/gql-0.2.0/wandb_gql/client.py", line 60, in _get_result
    return self.transport.execute(document, *args, **kwargs)
  File "/root/miniconda3/envs/myq_py38/lib/python3.8/site-packages/wandb/sdk/lib/gql_request.py", line 55, in execute
    request = self.session.post(self.url, **post_args)
  File "/root/miniconda3/envs/myq_py38/lib/python3.8/site-packages/requests/sessions.py", line 635, in post
    return self.request("POST", url, data=data, json=json, **kwargs)
  File "/root/miniconda3/envs/myq_py38/lib/python3.8/site-packages/requests/sessions.py", line 587, in request
    resp = self.send(prep, **send_kwargs)
  File "/root/miniconda3/envs/myq_py38/lib/python3.8/site-packages/requests/sessions.py", line 701, in send
    r = adapter.send(request, **kwargs)
  File "/root/miniconda3/envs/myq_py38/lib/python3.8/site-packages/requests/adapters.py", line 563, in send
    raise SSLError(e, request=request)
requests.exceptions.SSLError: HTTPSConnectionPool(host='api.wandb.ai', port=443): Max retries exceeded with url: /graphql (Caused by SSLError(CertificateError("hostname 'api.wandb.ai' doesn't match either of '*.gxnu.edu.cn', 'gxnu.edu.cn'")))
2023-04-23 20:27:23,409 DEBUG   HandlerThread:28076 [handler.py:handle_request():144] handle_request: keepalive
2023-04-23 20:27:28,411 DEBUG   HandlerThread:28076 [handler.py:handle_request():144] handle_request: keepalive
2023-04-23 20:27:33,414 DEBUG   HandlerThread:28076 [handler.py:handle_request():144] handle_request: keepalive
2023-04-23 20:27:38,416 DEBUG   HandlerThread:28076 [handler.py:handle_request():144] handle_request: keepalive
2023-04-23 20:27:43,418 DEBUG   HandlerThread:28076 [handler.py:handle_request():144] handle_request: keepalive
2023-04-23 20:27:48,420 DEBUG   HandlerThread:28076 [handler.py:handle_request():144] handle_request: keepalive
2023-04-23 20:27:53,422 DEBUG   HandlerThread:28076 [handler.py:handle_request():144] handle_request: keepalive
2023-04-23 20:27:58,424 DEBUG   HandlerThread:28076 [handler.py:handle_request():144] handle_request: keepalive
2023-04-23 20:28:03,427 DEBUG   HandlerThread:28076 [handler.py:handle_request():144] handle_request: keepalive
2023-04-23 20:28:07,464 WARNING StreamThr :28076 [internal.py:is_dead():414] Internal process exiting, parent pid 27444 disappeared
2023-04-23 20:28:07,465 ERROR   StreamThr :28076 [internal.py:wandb_internal():152] Internal process shutdown.
2023-04-23 20:28:08,424 INFO    WriterThread:28076 [datastore.py:close():298] close: /root/workspace/myq_206/server-master/wandb/run-20230423_202718-wvttj58m/run-wvttj58m.wandb
2023-04-23 20:28:08,428 INFO    HandlerThread:28076 [handler.py:finish():845] shutting down handler
2023-04-23 20:28:08,429 INFO    MainThread:28076 [internal.py:handle_exit():76] Internal process exited
